Workbook

Sheet Raw_Order
A1: Order_No | B1: Order_Date | C1: Buyer | D1: Style | E1: Product_Category | F1: Qty | G1: Unit_Price | H1: Currency | I1: Delivery_Date | J1: Merchandiser
A2: SO-2026-0001 | B2: 46105 | C2: Urban Wear | D2: ST-103 | E2: Hoodie | F2: 5263 | G2: 12.28 | H2: USD | I2: 46140 | J2: Merch-02
A3: SO-2026-0002 | B3: 46074 | C3: Urban Wear | D3: ST-109 | E3: Shirt | F3: 9914 | G3: 17.58 | H3: USD | I3: 46122 | J3: Merch-02
A4: SO-2026-0003 | B4: 46130 | C4: Global Retail | D4: ST-108 | E4: Hoodie | F4: 1342 | G4: 9.73 | H4: USD | I4: 46212 | J4: Merch-01
A5: SO-2026-0004 | B5: 46046 | C5: ABC Fashion | D5: ST-110 | E5: Jacket | F5: 5769 | G5: 15.61 | H5: USD | I5: 46136 | J5: Merch-01
A6: SO-2026-0005 | B6: 46090 | C6: Global Retail | D6: ST-101 | E6: T-Shirt | F6: 11218 | G6: 11.88 | H6: USD | I6: 46175 | J6: Merch-05
A7: SO-2026-0006 | B7: 46071 | C7: North Star Apparel | D7: ST-105 | E7: Jacket | F7: 4306 | G7: 10.31 | H7: USD | I7: 46160 | J7: Merch-02
A8: SO-2026-0007 | B8: 46032 | C8: Fashion Hub | D8: ST-107 | E8: Polo | F8: 4961 | G8: 7.51 | H8: USD | I8: 46101 | J8: Merch-03
A9: SO-2026-0008 | B9: 46119 | C9: Fashion Hub | D9: ST-102 | E9: Polo | F9: 9075 | G9: 5.04 | H9: USD | I9: 46157 | J9: Merch-03
A10: SO-2026-0009 | B10: 46030 | C10: Urban Wear | D10: ST-109 | E10: Shirt | F10: 2613 | G10: 12.33 | H10: USD | I10: 46093 | J10: Merch-04
A11: SO-2026-0010 | B11: 46043 | C11: ABC Fashion | D11: ST-105 | E11: Jacket | F11: 5933 | G11: 11.34 | H11: USD | I11: 46131 | J11: Merch-01
A12: SO-2026-0011 | B12: 46047 | C12: ABC Fashion | D12: ST-107 | E12: Polo | F12: 3043 | G12: 11.5 | H12: USD | I12: 46086 | J12: Merch-02
A13: SO-2026-0012 | B13: 46054 | C13: Fashion Hub | D13: ST-102 | E13: Polo | F13: 7152 | G13: 12.21 | H13: USD | I13: 46138 | J13: Merch-05
... A81: SO-2026-0080 | B81: 46131 | C81: Fashion Hub | D81: ST-110 | E81: Jacket | F81: 1732 | G81: 13.9 | H81: USD | I81: 46211 | J81: Merch-03

Sheet Raw_Item
A1: Item_Code | B1: Item_Type | C1: Item_Description | D1: UOM | E1: Supplier | F1: Purchase_Type | G1: Status
A2: FAB-0100 | B2: Fabric | C2: Main Cotton Jersey | D2: KG | E2: Delta Textiles | F2: Foreign | G2: Active
A3: ACC-0101 | B3: Accessory | C3: Zipper | D3: PCS | E3: Prime Accessories | F3: Local | G3: Active
A4: PKG-0102 | B4: Packing | C4: Poly Bag | D4: PCS | E4: Prime Accessories | F4: Local | G4: Active
A5: ACC-0103 | B5: Accessory | C5: Button 4-hole | D5: PCS | E5: Sunrise Packing | F5: Local | G5: Active
A6: ACC-0104 | B6: Accessory | C6: Size Label | D6: PCS | E6: Metro Trims | F6: Local | G6: Active
A7: ACC-0105 | B7: Accessory | C7: Zipper | D7: PCS | E7: Delta Textiles | F7: Local | G7: Active
A8: PKG-0106 | B8: Packing | C8: Sticker | D8: PCS | E8: Delta Textiles | F8: Local | G8: Active
A9: PKG-0107 | B9: Packing | C9: Poly Bag | D9: PCS | E9: Global Fabrics Ltd. | F9: Local | G9: Active
A10: PKG-0108 | B10: Packing | C10: Poly Bag | D10: PCS | E10: Sunrise Packing | F10: Local | G10: Active
A11: ACC-0109 | B11: Accessory | C11: Button 4-hole | D11: PCS | E11: Delta Textiles | F11: Local | G11: Active
A12: FAB-0110 | B12: Fabric | C12: Fleece Fabric | D12: KG | E12: Delta Textiles | F12: Foreign | G12: Active
... A36: PKG-0134 | B36: Packing | C36: Carton | D36: PCS | E36: Metro Trims | F36: Local | G36: Active

Sheet Raw_BOM
A1: Style | B1: Item_Code | C1: Item_Type | D1: Consumption | E1: Wastage_% | F1: UOM | G1: Approval_Status
A2: ST-101 | B2: FAB-0121 | C2: Fabric | D2: 0.278 | E2: 0.051 | F2: KG | G2: Approved
A3: ST-101 | B3: FAB-0131 | C3: Fabric | D3: 0.466 | E3: 0.014 | F3: KG | G3: Approved
A4: ST-101 | B4: ACC-0126 | C4: Accessory | D4: 6.512 | E4: 0.065 | F4: CONE | G4: Approved
A5: ST-101 | B5: ACC-0103 | C5: Accessory | D5: 5.438 | E5: 0.024 | F5: PCS | G5: Approved
A6: ST-101 | B6: ACC-0133 | C6: Accessory | D6: 12.823 | E6: 0.032 | F6: CONE | G6: Approved
A7: ST-101 | B7: ACC-0124 | C7: Accessory | D7: 8.783 | E7: 0.062 | F7: CONE | G7: Approved
A8: ST-101 | B8: PKG-0107 | C8: Packing | D8: 0.845 | E8: 0.079 | F8: PCS | G8: Approved
A9: ST-102 | B9: FAB-0115 | C9: Fabric | D9: 0.625 | E9: 0.025 | F9: KG | G9: Approved
A10: ST-102 | B10: FAB-0110 | C10: Fabric | D10: 0.74 | E10: 0.039 | F10: KG | G10: Approved
A11: ST-102 | B11: ACC-0103 | C11: Accessory | D11: 4.435 | E11: 0.044 | F11: PCS | G11: Approved
A12: ST-102 | B12: ACC-0114 | C12: Accessory | D12: 6.289 | E12: 0.03 | F12: PCS | G12: Approved
A13: ST-102 | B13: ACC-0104 | C13: Accessory | D13: 4.317 | E13: 0.002 | F13: PCS | G13: Approved
... A71: ST-110 | B71: PKG-0102 | C71: Packing | D71: 0.966 | E71: 0.051 | F71: PCS | G71: Approved

Sheet Raw_Price
A1: Supplier | B1: Item_Code | C1: Purchase_Type | D1: Unit_Price | E1: Currency | F1: Lead_Time_Days
A2: Prime Accessories | B2: FAB-0100 | C2: Local | D2: 3.54 | E2: BDT | F2: 30
A3: Global Fabrics Ltd. | B3: FAB-0100 | C3: Foreign | D3: 6.37 | E3: USD | F3: 17
A4: Sunrise Packing | B4: ACC-0101 | C4: Local | D4: 0.22 | E4: BDT | F4: 40
A5: Metro Trims | B5: PKG-0102 | C5: Local | D5: 3.83 | E5: BDT | F5: 45
A6: Prime Accessories | B6: ACC-0103 | C6: Local | D6: 1.38 | E6: BDT | F6: 50
A7: Delta Textiles | B7: ACC-0103 | C7: Local | D7: 2.53 | E7: BDT | F7: 48
A8: Global Fabrics Ltd. | B8: ACC-0104 | C8: Local | D8: 1.08 | E8: BDT | F8: 31
A9: Metro Trims | B9: ACC-0104 | C9: Local | D9: 1.65 | E9: BDT | F9: 40
A10: Prime Accessories | B10: ACC-0105 | C10: Local | D10: 4.18 | E10: BDT | F10: 36
A11: Global Fabrics Ltd. | B11: ACC-0105 | C11: Local | D11: 4.21 | E11: BDT | F11: 38
A12: Sunrise Packing | B12: PKG-0106 | C12: Local | D12: 2.58 | E12: BDT | F12: 41
A13: Sunrise Packing | B13: PKG-0107 | C13: Local | D13: 1.99 | E13: BDT | F13: 42
... A65: Sunrise Packing | B65: PKG-0134 | C65: Local | D65: 2.97 | E65: BDT | F65: 14

Sheet Raw_PO
A1: PO_No | B1: PO_Date | C1: Order_No | D1: Style | E1: Supplier | F1: Purchase_Type | G1: Item_Code | H1: Qty | I1: UOM | J1: Unit_Price | K1: Currency | L1: Status
A2: PO-2026-00001 | B2: 46048 | C2: SO-2026-0049 | D2: ST-105 | E2: Delta Textiles | F2: Local | G2: ACC-0105 | H2: 55331 | I2: PCS | J2: 1 | K2: USD | L2: Received
A3: PO-2026-00002 | B3: 46092 | C3: SO-2026-0035 | D3: ST-110 | E3: Prime Accessories | F3: Local | G3: ACC-0101 | H3: 42397 | I3: PCS | J3: 1 | K3: USD | L3: Received
A4: PO-2026-00003 | B4: 46129 | C4: SO-2026-0073 | D4: ST-104 | E4: Global Fabrics Ltd. | F4: Local | G4: ACC-0117 | H4: 34942 | I4: MTR | J4: 1 | K4: USD | L4: Open
A5: PO-2026-00004 | B5: 46097 | C5: SO-2026-0027 | D5: ST-102 | E5: Metro Trims | F5: Local | G5: ACC-0104 | H5: 36015 | I5: PCS | J5: 1.65 | K5: BDT | L5: Partial
A6: PO-2026-00005 | B6: 46079 | C6: SO-2026-0002 | D6: ST-109 | E6: Sunrise Packing | F6: Local | G6: ACC-0123 | H6: 11809 | I6: PCS | J6: 1 | K6: USD | L6: Open
A7: PO-2026-00006 | B7: 46053 | C7: SO-2026-0060 | D7: ST-107 | E7: Prime Accessories | F7: Local | G7: ACC-0101 | H7: 33813 | I7: PCS | J7: 1 | K7: USD | L7: Open
A8: PO-2026-00007 | B8: 46106 | C8: SO-2026-0001 | D8: ST-103 | E8: Delta Textiles | F8: Foreign | G8: FAB-0110 | H8: 3058 | I8: KG | J8: 1 | K8: USD | L8: Partial
A9: PO-2026-00008 | B9: 46044 | C9: SO-2026-0076 | D9: ST-108 | E9: Delta Textiles | F9: Local | G9: PKG-0118 | H9: 4236 | I9: PCS | J9: 3.19 | K9: BDT | L9: Received
A10: PO-2026-00009 | B10: 46087 | C10: SO-2026-0074 | D10: ST-104 | E10: Sunrise Packing | F10: Local | G10: ACC-0133 | H10: 30342 | I10: CONE | J10: 3.06 | K10: BDT | L10: Open
A11: PO-2026-00010 | B11: 46040 | C11: SO-2026-0070 | D11: ST-104 | E11: Sunrise Packing | F11: Local | G11: ACC-0133 | H11: 32099 | I11: CONE | J11: 3.06 | K11: BDT | L11: Received
A12: PO-2026-00011 | B12: 46081 | C12: SO-2026-0039 | D12: ST-104 | E12: Delta Textiles | F12: Foreign | G12: FAB-0110 | H12: 2617 | I12: KG | J12: 1 | K12: USD | L12: Received
A13: PO-2026-00012 | B13: 46112 | C13: SO-2026-0033 | D13: ST-102 | E13: Metro Trims | F13: Local | G13: FAB-0115 | H13: 4713 | I13: KG | J13: 5.15 | K13: BDT | L13: Partial
... A181: PO-2026-00180 | B181: 46120 | C181: SO-2026-0073 | D181: ST-104 | E181: Global Fabrics Ltd. | F181: Local | G181: PKG-0107 | H181: 2793 | I181: PCS | J181: 1 | K181: USD | L181: Open

Sheet Raw_Cost
A1: Order_No | B1: Style | C1: Qty | D1: Fabric_Cost | E1: Accessories_Cost | F1: Packing_Cost | G1: Labor_Cost | H1: Overhead
A2: SO-2026-0001 | B2: ST-103 | C2: 5263 | D2: 9901.47 | E2: 6026.58 | F2: 1139.14 | G2: 10005.71 | H2: 3562.27
A3: SO-2026-0002 | B3: ST-109 | C3: 9914 | D3: 35120.48 | E3: 13418.6 | F3: 1610.6 | G3: 8685.87 | H3: 2776.49
A4: SO-2026-0003 | B4: ST-108 | C4: 1342 | D4: 4480.25 | E4: 885.8 | F4: 217.26 | G4: 2702.53 | H4: 198.66
A5: SO-2026-0004 | B5: ST-110 | C5: 5769 | D5: 20555.11 | E5: 5002.32 | F5: 848.26 | G5: 10288.47 | H5: 2689.45
A6: SO-2026-0005 | B6: ST-101 | C6: 11218 | D6: 44055.11 | E6: 4371.27 | F6: 2589.4 | G6: 22515.03 | H6: 6307.52
A7: SO-2026-0006 | B7: ST-105 | C7: 4306 | D7: 12594.5 | E7: 4838.32 | F7: 1690.57 | G7: 8718.14 | H7: 1628.77
A8: SO-2026-0007 | B8: ST-107 | C8: 4961 | D8: 9854.09 | E8: 3551.38 | F8: 1961 | G8: 7848.51 | H8: 2630.2
A9: SO-2026-0008 | B9: ST-102 | C9: 9075 | D9: 11902.21 | E9: 4806.66 | F9: 1219.53 | G9: 12675.4 | H9: 3160.97
A10: SO-2026-0009 | B10: ST-109 | C10: 2613 | D10: 7453.29 | E10: 1277.11 | F10: 167.66 | G10: 1580.61 | H10: 905.62
A11: SO-2026-0010 | B11: ST-105 | C11: 5933 | D11: 7708.09 | E11: 3409.19 | F11: 1897.84 | G11: 11077.71 | H11: 1403.33
A12: SO-2026-0011 | B12: ST-107 | C12: 3043 | D12: 6389.82 | E12: 3992.03 | F12: 470.03 | G12: 6005.89 | H12: 447.5
A13: SO-2026-0012 | B13: ST-102 | C13: 7152 | D13: 12398.75 | E13: 5900.75 | F13: 2268.21 | G13: 16227.47 | H13: 998.65
... A81: SO-2026-0080 | B81: ST-110 | C81: 1732 | D81: 2630.08 | E81: 2556.17 | F81: 97.91 | G81: 3906.3 | H81: 939.84

Sheet Raw_Production
A1: Date | B1: Day | C1: Department | D1: Team_no | E1: No_of_workers | F1: No_of_style_change | G1: Targeted_productivity | H1: Smv | I1: Wip | J1: Over_time | K1: Incentive | L1: Idle_time | M1: Idle_men | N1: Actual_productivity | O1: Product_Category | P1: Style
A2: 46027 | B2: Monday | C2: Cutting | D2: T01 | E2: 22 | F2: 2 | G2: 0.81 | H2: 18.4 | I2: 168 | J2: 131 | K2: 2787 | L2: 83 | M2: 4 | N2: 0.79 | O2: Hoodie | P2: ST-108
A3: 46027 | B3: Monday | C3: Cutting | D3: T06 | E3: 38 | F3: 1 | G3: 0.83 | H3: 10.9 | I3: 343 | J3: 129 | K3: 892 | L3: 57 | M3: 8 | N3: 0.74 | O3: Polo | P3: ST-107
A4: 46027 | B4: Monday | C4: Sewing | D4: T02 | E4: 20 | F4: 0 | G4: 0.89 | H4: 16 | I4: 318 | J4: 83 | K4: 4219 | L4: 54 | M4: 0 | N4: 0.88 | O4: Jacket | P4: ST-105
A5: 46027 | B5: Monday | C5: Sewing | D5: T03 | E5: 28 | F5: 0 | G5: 0.76 | H5: 10.9 | I5: 173 | J5: 68 | K5: 2091 | L5: 55 | M5: 1 | N5: 0.7 | O5: Polo | P5: ST-107
A6: 46027 | B6: Monday | C6: Finishing | D6: T04 | E6: 36 | F6: 2 | G6: 0.87 | H6: 15.7 | I6: 83 | J6: 43 | K6: 1132 | L6: 91 | M6: 8 | N6: 0.68 | O6: Shirt | P6: ST-109
A7: 46027 | B7: Monday | C7: Finishing | D7: T05 | E7: 32 | F7: 0 | G7: 0.82 | H7: 12.5 | I7: 267 | J7: 6 | K7: 2840 | L7: 11 | M7: 4 | N7: 0.72 | O7: Polo | P7: ST-102
A8: 46028 | B8: Tuesday | C8: Cutting | D8: T01 | E8: 30 | F8: 0 | G8: 0.78 | H8: 14.9 | I8: 222 | J8: 131 | K8: 407 | L8: 102 | M8: 4 | N8: 0.66 | O8: Jacket | P8: ST-110
A9: 46028 | B9: Tuesday | C9: Cutting | D9: T06 | E9: 31 | F9: 0 | G9: 0.83 | H9: 17 | I9: 215 | J9: 143 | K9: 4486 | L9: 47 | M9: 6 | N9: 0.72 | O9: T-Shirt | P9: ST-106
A10: 46028 | B10: Tuesday | C10: Sewing | D10: T02 | E10: 36 | F10: 0 | G10: 0.74 | H10: 13.2 | I10: 43 | J10: 86 | K10: 4324 | L10: 36 | M10: 9 | N10: 0.78 | O10: Jacket | P10: ST-110
A11: 46028 | B11: Tuesday | C11: Sewing | D11: T03 | E11: 28 | F11: 4 | G11: 0.82 | H11: 13.4 | I11: 267 | J11: 121 | K11: 4389 | L11: 51 | M11: 3 | N11: 0.61 | O11: Jacket | P11: ST-105
A12: 46028 | B12: Tuesday | C12: Finishing | D12: T04 | E12: 20 | F12: 0 | G12: 0.86 | H12: 12.3 | I12: 172 | J12: 14 | K12: 2929 | L12: 15 | M12: 3 | N12: 0.72 | O12: Jacket | P12: ST-110
A13: 46028 | B13: Tuesday | C13: Finishing | D13: T05 | E13: 28 | F13: 1 | G13: 0.8 | H13: 18.5 | I13: 196 | J13: 129 | K13: 3166 | L13: 8 | M13: 6 | N13: 0.87 | O13: Polo | P13: ST-107
... A721: 46146 | B721: Monday | C721: Finishing | D721: T05 | E721: 20 | F721: 1 | G721: 0.86 | H721: 9.1 | I721: 259 | J721: 36 | K721: 1327 | L721: 102 | M721: 5 | N721: 0.9 | O721: Jacket | P721: ST-105

Sheet Item_Master
A1: Item_Code | B1: Item_Type | C1: Item_Description | D1: UOM | E1: Supplier | F1: Purchase_Type | G1: Status
A2: FAB-0100 | B2: Fabric | C2: Main Cotton Jersey | D2: KG | E2: Delta Textiles | F2: Foreign | G2: Active
A3: ACC-0101 | B3: Accessory | C3: Zipper | D3: PCS | E3: Prime Accessories | F3: Local | G3: Active
A4: PKG-0102 | B4: Packing | C4: Poly Bag | D4: PCS | E4: Prime Accessories | F4: Local | G4: Active
A5: ACC-0103 | B5: Accessory | C5: Button 4-hole | D5: PCS | E5: Sunrise Packing | F5: Local | G5: Active
A6: ACC-0104 | B6: Accessory | C6: Size Label | D6: PCS | E6: Metro Trims | F6: Local | G6: Active
A7: ACC-0105 | B7: Accessory | C7: Zipper | D7: PCS | E7: Delta Textiles | F7: Local | G7: Active
A8: PKG-0106 | B8: Packing | C8: Sticker | D8: PCS | E8: Delta Textiles | F8: Local | G8: Active
A9: PKG-0107 | B9: Packing | C9: Poly Bag | D9: PCS | E9: Global Fabrics Ltd. | F9: Local | G9: Active
A10: PKG-0108 | B10: Packing | C10: Poly Bag | D10: PCS | E10: Sunrise Packing | F10: Local | G10: Active
A11: ACC-0109 | B11: Accessory | C11: Button 4-hole | D11: PCS | E11: Delta Textiles | F11: Local | G11: Active
A12: FAB-0110 | B12: Fabric | C12: Fleece Fabric | D12: KG | E12: Delta Textiles | F12: Foreign | G12: Active
... A36: PKG-0134 | B36: Packing | C36: Carton | D36: PCS | E36: Metro Trims | F36: Local | G36: Active

Sheet Calculations
A1: Date | B1: Department | C1: Team_no | D1: Style | E1: Product_Category | F1: Target Productivity | G1: Actual Productivity | H1: Productivity Gap | I1: WIP | J1: Overtime (min) | K1: Idle Time (min) | L1: Idle Men | M1: Style Changes | N1: Incentive | O1: SMV | P1: Workers
A2: =Raw_Production!A2 -> 46027 | B2: =Raw_Production!C2 -> Cutting | C2: =Raw_Production!D2 -> T01 | D2: =Raw_Production!P2 -> ST-108 | E2: =Raw_Production!O2 -> Hoodie | F2: =Raw_Production!G2 -> 0.81 | G2: =Raw_Production!N2 -> 0.79 | H2: =G2-F2 -> -0.02 | I2: =Raw_Production!I2 -> 168 | J2: =Raw_Production!J2 -> 131 | K2: =Raw_Production!L2 -> 83 | L2: =Raw_Production!M2 -> 4 | M2: =Raw_Production!F2 -> 2 | N2: =Raw_Production!K2 -> 2787 | O2: =Raw_Production!H2 -> 18.4 | P2: =Raw_Production!E2 -> 22
A3: =Raw_Production!A3 -> 46027 | B3: =Raw_Production!C3 -> Cutting | C3: =Raw_Production!D3 -> T06 | D3: =Raw_Production!P3 -> ST-107 | E3: =Raw_Production!O3 -> Polo | F3: =Raw_Production!G3 -> 0.83 | G3: =Raw_Production!N3 -> 0.74 | H3: =G3-F3 -> -0.09 | I3: =Raw_Production!I3 -> 343 | J3: =Raw_Production!J3 -> 129 | K3: =Raw_Production!L3 -> 57 | L3: =Raw_Production!M3 -> 8 | M3: =Raw_Production!F3 -> 1 | N3: =Raw_Production!K3 -> 892 | O3: =Raw_Production!H3 -> 10.9 | P3: =Raw_Production!E3 -> 38
A4: =Raw_Production!A4 -> 46027 | B4: =Raw_Production!C4 -> Sewing | C4: =Raw_Production!D4 -> T02 | D4: =Raw_Production!P4 -> ST-105 | E4: =Raw_Production!O4 -> Jacket | F4: =Raw_Production!G4 -> 0.89 | G4: =Raw_Production!N4 -> 0.88 | H4: =G4-F4 -> -0.01 | I4: =Raw_Production!I4 -> 318 | J4: =Raw_Production!J4 -> 83 | K4: =Raw_Production!L4 -> 54 | L4: =Raw_Production!M4 -> 0 | M4: =Raw_Production!F4 -> 0 | N4: =Raw_Production!K4 -> 4219 | O4: =Raw_Production!H4 -> 16 | P4: =Raw_Production!E4 -> 20
A5: =Raw_Production!A5 -> 46027 | B5: =Raw_Production!C5 -> Sewing | C5: =Raw_Production!D5 -> T03 | D5: =Raw_Production!P5 -> ST-107 | E5: =Raw_Production!O5 -> Polo | F5: =Raw_Production!G5 -> 0.76 | G5: =Raw_Production!N5 -> 0.7 | H5: =G5-F5 -> -0.06 | I5: =Raw_Production!I5 -> 173 | J5: =Raw_Production!J5 -> 68 | K5: =Raw_Production!L5 -> 55 | L5: =Raw_Production!M5 -> 1 | M5: =Raw_Production!F5 -> 0 | N5: =Raw_Production!K5 -> 2091 | O5: =Raw_Production!H5 -> 10.9 | P5: =Raw_Production!E5 -> 28
A6: =Raw_Production!A6 -> 46027 | B6: =Raw_Production!C6 -> Finishing | C6: =Raw_Production!D6 -> T04 | D6: =Raw_Production!P6 -> ST-109 | E6: =Raw_Production!O6 -> Shirt | F6: =Raw_Production!G6 -> 0.87 | G6: =Raw_Production!N6 -> 0.68 | H6: =G6-F6 -> -0.19 | I6: =Raw_Production!I6 -> 83 | J6: =Raw_Production!J6 -> 43 | K6: =Raw_Production!L6 -> 91 | L6: =Raw_Production!M6 -> 8 | M6: =Raw_Production!F6 -> 2 | N6: =Raw_Production!K6 -> 1132 | O6: =Raw_Production!H6 -> 15.7 | P6: =Raw_Production!E6 -> 36
A7: =Raw_Production!A7 -> 46027 | B7: =Raw_Production!C7 -> Finishing | C7: =Raw_Production!D7 -> T05 | D7: =Raw_Production!P7 -> ST-102 | E7: =Raw_Production!O7 -> Polo | F7: =Raw_Production!G7 -> 0.82 | G7: =Raw_Production!N7 -> 0.72 | H7: =G7-F7 -> -0.1 | I7: =Raw_Production!I7 -> 267 | J7: =Raw_Production!J7 -> 6 | K7: =Raw_Production!L7 -> 11 | L7: =Raw_Production!M7 -> 4 | M7: =Raw_Production!F7 -> 0 | N7: =Raw_Production!K7 -> 2840 | O7: =Raw_Production!H7 -> 12.5 | P7: =Raw_Production!E7 -> 32
A8: =Raw_Production!A8 -> 46028 | B8: =Raw_Production!C8 -> Cutting | C8: =Raw_Production!D8 -> T01 | D8: =Raw_Production!P8 -> ST-110 | E8: =Raw_Production!O8 -> Jacket | F8: =Raw_Production!G8 -> 0.78 | G8: =Raw_Production!N8 -> 0.66 | H8: =G8-F8 -> -0.12 | I8: =Raw_Production!I8 -> 222 | J8: =Raw_Production!J8 -> 131 | K8: =Raw_Production!L8 -> 102 | L8: =Raw_Production!M8 -> 4 | M8: =Raw_Production!F8 -> 0 | N8: =Raw_Production!K8 -> 407 | O8: =Raw_Production!H8 -> 14.9 | P8: =Raw_Production!E8 -> 30
A9: =Raw_Production!A9 -> 46028 | B9: =Raw_Production!C9 -> Cutting | C9: =Raw_Production!D9 -> T06 | D9: =Raw_Production!P9 -> ST-106 | E9: =Raw_Production!O9 -> T-Shirt | F9: =Raw_Production!G9 -> 0.83 | G9: =Raw_Production!N9 -> 0.72 | H9: =G9-F9 -> -0.11 | I9: =Raw_Production!I9 -> 215 | J9: =Raw_Production!J9 -> 143 | K9: =Raw_Production!L9 -> 47 | L9: =Raw_Production!M9 -> 6 | M9: =Raw_Production!F9 -> 0 | N9: =Raw_Production!K9 -> 4486 | O9: =Raw_Production!H9 -> 17 | P9: =Raw_Production!E9 -> 31
A10: =Raw_Production!A10 -> 46028 | B10: =Raw_Production!C10 -> Sewing | C10: =Raw_Production!D10 -> T02 | D10: =Raw_Production!P10 -> ST-110 | E10: =Raw_Production!O10 -> Jacket | F10: =Raw_Production!G10 -> 0.74 | G10: =Raw_Production!N10 -> 0.78 | H10: =G10-F10 -> 0.04 | I10: =Raw_Production!I10 -> 43 | J10: =Raw_Production!J10 -> 86 | K10: =Raw_Production!L10 -> 36 | L10: =Raw_Production!M10 -> 9 | M10: =Raw_Production!F10 -> 0 | N10: =Raw_Production!K10 -> 4324 | O10: =Raw_Production!H10 -> 13.2 | P10: =Raw_Production!E10 -> 36
A11: =Raw_Production!A11 -> 46028 | B11: =Raw_Production!C11 -> Sewing | C11: =Raw_Production!D11 -> T03 | D11: =Raw_Production!P11 -> ST-105 | E11: =Raw_Production!O11 -> Jacket | F11: =Raw_Production!G11 -> 0.82 | G11: =Raw_Production!N11 -> 0.61 | H11: =G11-F11 -> -0.21 | I11: =Raw_Production!I11 -> 267 | J11: =Raw_Production!J11 -> 121 | K11: =Raw_Production!L11 -> 51 | L11: =Raw_Production!M11 -> 3 | M11: =Raw_Production!F11 -> 4 | N11: =Raw_Production!K11 -> 4389 | O11: =Raw_Production!H11 -> 13.4 | P11: =Raw_Production!E11 -> 28
A12: =Raw_Production!A12 -> 46028 | B12: =Raw_Production!C12 -> Finishing | C12: =Raw_Production!D12 -> T04 | D12: =Raw_Production!P12 -> ST-110 | E12: =Raw_Production!O12 -> Jacket | F12: =Raw_Production!G12 -> 0.86 | G12: =Raw_Production!N12 -> 0.72 | H12: =G12-F12 -> -0.14 | I12: =Raw_Production!I12 -> 172 | J12: =Raw_Production!J12 -> 14 | K12: =Raw_Production!L12 -> 15 | L12: =Raw_Production!M12 -> 3 | M12: =Raw_Production!F12 -> 0 | N12: =Raw_Production!K12 -> 2929 | O12: =Raw_Production!H12 -> 12.3 | P12: =Raw_Production!E12 -> 20
A13: =Raw_Production!A13 -> 46028 | B13: =Raw_Production!C13 -> Finishing | C13: =Raw_Production!D13 -> T05 | D13: =Raw_Production!P13 -> ST-107 | E13: =Raw_Production!O13 -> Polo | F13: =Raw_Production!G13 -> 0.8 | G13: =Raw_Production!N13 -> 0.87 | H13: =G13-F13 -> 0.07 | I13: =Raw_Production!I13 -> 196 | J13: =Raw_Production!J13 -> 129 | K13: =Raw_Production!L13 -> 8 | L13: =Raw_Production!M13 -> 6 | M13: =Raw_Production!F13 -> 1 | N13: =Raw_Production!K13 -> 3166 | O13: =Raw_Production!H13 -> 18.5 | P13: =Raw_Production!E13 -> 28
... A721: =Raw_Production!A721 -> 46146 | B721: =Raw_Production!C721 -> Finishing | C721: =Raw_Production!D721 -> T05 | D721: =Raw_Production!P721 -> ST-105 | E721: =Raw_Production!O721 -> Jacket | F721: =Raw_Production!G721 -> 0.86 | G721: =Raw_Production!N721 -> 0.9 | H721: =G721-F721 -> 0.04 | I721: =Raw_Production!I721 -> 259 | J721: =Raw_Production!J721 -> 36 | K721: =Raw_Production!L721 -> 102 | L721: =Raw_Production!M721 -> 5 | M721: =Raw_Production!F721 -> 1 | N721: =Raw_Production!K721 -> 1327 | O721: =Raw_Production!H721 -> 9.1 | P721: =Raw_Production!E721 -> 20

Sheet Order_Sheet
A1: Order_No | B1: Order_Date | C1: Buyer | D1: Style | E1: Product_Category | F1: Qty | G1: Unit_Price | H1: Currency | I1: Delivery_Date | J1: Merchandiser | K1: Status | L1: Data_Check
A2: SO-2026-0001 | B2: 46105 | C2: Urban Wear | D2: ST-103 | E2: Hoodie | F2: 5263 | G2: 12.28 | H2: USD | I2: 46140 | J2: Merch-02 | K2: Not Provided (Raw) | L2: =IF(COUNTA(A2:J2)<10,"MISSING DATA",IF(I2<B2,"DATE ERROR","OK")) -> OK
A3: SO-2026-0002 | B3: 46074 | C3: Urban Wear | D3: ST-109 | E3: Shirt | F3: 9914 | G3: 17.58 | H3: USD | I3: 46122 | J3: Merch-02 | K3: Not Provided (Raw) | L3: =IF(COUNTA(A3:J3)<10,"MISSING DATA",IF(I3<B3,"DATE ERROR","OK")) -> OK
A4: SO-2026-0003 | B4: 46130 | C4: Global Retail | D4: ST-108 | E4: Hoodie | F4: 1342 | G4: 9.73 | H4: USD | I4: 46212 | J4: Merch-01 | K4: Not Provided (Raw) | L4: =IF(COUNTA(A4:J4)<10,"MISSING DATA",IF(I4<B4,"DATE ERROR","OK")) -> OK
A5: SO-2026-0004 | B5: 46046 | C5: ABC Fashion | D5: ST-110 | E5: Jacket | F5: 5769 | G5: 15.61 | H5: USD | I5: 46136 | J5: Merch-01 | K5: Not Provided (Raw) | L5: =IF(COUNTA(A5:J5)<10,"MISSING DATA",IF(I5<B5,"DATE ERROR","OK")) -> OK
A6: SO-2026-0005 | B6: 46090 | C6: Global Retail | D6: ST-101 | E6: T-Shirt | F6: 11218 | G6: 11.88 | H6: USD | I6: 46175 | J6: Merch-05 | K6: Not Provided (Raw) | L6: =IF(COUNTA(A6:J6)<10,"MISSING DATA",IF(I6<B6,"DATE ERROR","OK")) -> OK
A7: SO-2026-0006 | B7: 46071 | C7: North Star Apparel | D7: ST-105 | E7: Jacket | F7: 4306 | G7: 10.31 | H7: USD | I7: 46160 | J7: Merch-02 | K7: Not Provided (Raw) | L7: =IF(COUNTA(A7:J7)<10,"MISSING DATA",IF(I7<B7,"DATE ERROR","OK")) -> OK
A8: SO-2026-0007 | B8: 46032 | C8: Fashion Hub | D8: ST-107 | E8: Polo | F8: 4961 | G8: 7.51 | H8: USD | I8: 46101 | J8: Merch-03 | K8: Not Provided (Raw) | L8: =IF(COUNTA(A8:J8)<10,"MISSING DATA",IF(I8<B8,"DATE ERROR","OK")) -> OK
A9: SO-2026-0008 | B9: 46119 | C9: Fashion Hub | D9: ST-102 | E9: Polo | F9: 9075 | G9: 5.04 | H9: USD | I9: 46157 | J9: Merch-03 | K9: Not Provided (Raw) | L9: =IF(COUNTA(A9:J9)<10,"MISSING DATA",IF(I9<B9,"DATE ERROR","OK")) -> OK
A10: SO-2026-0009 | B10: 46030 | C10: Urban Wear | D10: ST-109 | E10: Shirt | F10: 2613 | G10: 12.33 | H10: USD | I10: 46093 | J10: Merch-04 | K10: Not Provided (Raw) | L10: =IF(COUNTA(A10:J10)<10,"MISSING DATA",IF(I10<B10,"DATE ERROR","OK")) -> OK
A11: SO-2026-0010 | B11: 46043 | C11: ABC Fashion | D11: ST-105 | E11: Jacket | F11: 5933 | G11: 11.34 | H11: USD | I11: 46131 | J11: Merch-01 | K11: Not Provided (Raw) | L11: =IF(COUNTA(A11:J11)<10,"MISSING DATA",IF(I11<B11,"DATE ERROR","OK")) -> OK
A12: SO-2026-0011 | B12: 46047 | C12: ABC Fashion | D12: ST-107 | E12: Polo | F12: 3043 | G12: 11.5 | H12: USD | I12: 46086 | J12: Merch-02 | K12: Not Provided (Raw) | L12: =IF(COUNTA(A12:J12)<10,"MISSING DATA",IF(I12<B12,"DATE ERROR","OK")) -> OK
A13: SO-2026-0012 | B13: 46054 | C13: Fashion Hub | D13: ST-102 | E13: Polo | F13: 7152 | G13: 12.21 | H13: USD | I13: 46138 | J13: Merch-05 | K13: Not Provided (Raw) | L13: =IF(COUNTA(A13:J13)<10,"MISSING DATA",IF(I13<B13,"DATE ERROR","OK")) -> OK
... A81: SO-2026-0080 | B81: 46131 | C81: Fashion Hub | D81: ST-110 | E81: Jacket | F81: 1732 | G81: 13.9 | H81: USD | I81: 46211 | J81: Merch-03 | K81: Not Provided (Raw) | L81: =IF(COUNTA(A81:J81)<10,"MISSING DATA",IF(I81<B81,"DATE ERROR","OK")) -> OK

Sheet BOM
A1: BOM_ID | B1: Style | C1: Product_Category | D1: Item_Code | E1: Item_Type | F1: Description | G1: UOM | H1: Consumption | I1: Wastage_% | J1: Approval_Status | K1: Reference_Supplier | L1: Purchase_Type | M1: Reference_Price | N1: Currency
A2: BOM-0001 | B2: ST-101 | C2: T-Shirt | D2: FAB-0121 | E2: Fabric | F2: Rib Fabric | G2: KG | H2: 0.278 | I2: 0.051 | J2: Approved | K2: Delta Textiles | L2: Foreign | M2: 1.22 | N2: USD
A3: BOM-0002 | B3: ST-101 | C3: T-Shirt | D3: FAB-0131 | E3: Fabric | F3: Fleece Fabric | G3: KG | H3: 0.466 | I3: 0.014 | J3: Approved | K3: Prime Accessories | L3: Local | M3: 4.13 | N3: BDT
A4: BOM-0003 | B4: ST-101 | C4: T-Shirt | D4: ACC-0126 | E4: Accessory | F4: Sewing Thread | G4: CONE | H4: 6.512 | I4: 0.065 | J4: Approved | K4: Sunrise Packing | L4: Local | M4: 0.36 | N4: BDT
A5: BOM-0004 | B5: ST-101 | C5: T-Shirt | D5: ACC-0103 | E5: Accessory | F5: Button 4-hole | G5: PCS | H5: 5.438 | I5: 0.024 | J5: Approved | K5: Prime Accessories | L5: Local | M5: 1.38 | N5: BDT
A6: BOM-0005 | B6: ST-101 | C6: T-Shirt | D6: ACC-0133 | E6: Accessory | F6: Sewing Thread | G6: CONE | H6: 12.823 | I6: 0.032 | J6: Approved | K6: Prime Accessories | L6: Local | M6: 1.3 | N6: BDT
A7: BOM-0006 | B7: ST-101 | C7: T-Shirt | D7: ACC-0124 | E7: Accessory | F7: Sewing Thread | G7: CONE | H7: 8.783 | I7: 0.062 | J7: Approved | K7: Sunrise Packing | L7: Local | M7: 0.21 | N7: BDT
A8: BOM-0007 | B8: ST-101 | C8: T-Shirt | D8: PKG-0107 | E8: Packing | F8: Poly Bag | G8: PCS | H8: 0.845 | I8: 0.079 | J8: Approved | K8: Sunrise Packing | L8: Local | M8: 1.99 | N8: BDT
A9: BOM-0008 | B9: ST-102 | C9: Polo | D9: FAB-0115 | E9: Fabric | F9: Main Cotton Jersey | G9: KG | H9: 0.625 | I9: 0.025 | J9: Approved | K9: Sunrise Packing | L9: Local | M9: 2.38 | N9: BDT
A10: BOM-0009 | B10: ST-102 | C10: Polo | D10: FAB-0110 | E10: Fabric | F10: Fleece Fabric | G10: KG | H10: 0.74 | I10: 0.039 | J10: Approved | K10: Prime Accessories | L10: Local | M10: 4.62 | N10: BDT
A11: BOM-0010 | B11: ST-102 | C11: Polo | D11: ACC-0103 | E11: Accessory | F11: Button 4-hole | G11: PCS | H11: 4.435 | I11: 0.044 | J11: Approved | K11: Prime Accessories | L11: Local | M11: 1.38 | N11: BDT
A12: BOM-0011 | B12: ST-102 | C12: Polo | D12: ACC-0114 | E12: Accessory | F12: Button 4-hole | G12: PCS | H12: 6.289 | I12: 0.03 | J12: Approved | K12: Metro Trims | L12: Local | M12: 0.29 | N12: BDT
A13: BOM-0012 | B13: ST-102 | C13: Polo | D13: ACC-0104 | E13: Accessory | F13: Size Label | G13: PCS | H13: 4.317 | I13: 0.002 | J13: Approved | K13: Global Fabrics Ltd. | L13: Local | M13: 1.08 | N13: BDT
... A71: BOM-0070 | B71: ST-110 | C71: Jacket | D71: PKG-0102 | E71: Packing | F71: Poly Bag | G71: PCS | H71: 0.966 | I71: 0.051 | J71: Approved | K71: Metro Trims | L71: Local | M71: 3.83 | N71: BDT

Sheet BOM_Estimation
A1: Estimate_ID | B1: Order_No | C1: Style | D1: Qty | E1: Fabric_BDT | F1: Fabric_USD | G1: Accessory_BDT | H1: Accessory_USD | I1: Packing_BDT | J1: Packing_USD | K1: Total_BDT | L1: Total_USD | M1: BDT_per_Piece | N1: USD_per_Piece
A2: EST-0001 | B2: =Order_Sheet!A2 -> SO-2026-0001 | C2: =Order_Sheet!D2 -> ST-103 | D2: =Order_Sheet!F2 -> 5263 | E2: =D2*SUMPRODUCT((BOM!$B$2:$B$71=C2)*(BOM!$E$2:$E$71="Fabric")*(BOM!$N$2:$N$71="BDT")*BOM!$H$2:$H$71*(1+BOM!$I$2:$I$71)*BOM!$M$2:$M$71) -> 21179.689 | F2: =D2*SUMPRODUCT((BOM!$B$2:$B$71=C2)*(BOM!$E$2:$E$71="Fabric")*(BOM!$N$2:$N$71="USD")*BOM!$H$2:$H$71*(1+BOM!$I$2:$I$71)*BOM!$M$2:$M$71) -> 0 | G2: =D2*SUMPRODUCT((BOM!$B$2:$B$71=C2)*(BOM!$E$2:$E$71="Accessory")*(BOM!$N$2:$N$71="BDT")*BOM!$H$2:$H$71*(1+BOM!$I$2:$I$71)*BOM!$M$2:$M$71) -> 148206.88 | H2: =D2*SUMPRODUCT((BOM!$B$2:$B$71=C2)*(BOM!$E$2:$E$71="Accessory")*(BOM!$N$2:$N$71="USD")*BOM!$H$2:$H$71*(1+BOM!$I$2:$I$71)*BOM!$M$2:$M$71) -> 0 | I2: =D2*SUMPRODUCT((BOM!$B$2:$B$71=C2)*(BOM!$E$2:$E$71="Packing")*(BOM!$N$2:$N$71="BDT")*BOM!$H$2:$H$71*(1+BOM!$I$2:$I$71)*BOM!$M$2:$M$71) -> 5416.82 | J2: =D2*SUMPRODUCT((BOM!$B$2:$B$71=C2)*(BOM!$E$2:$E$71="Packing")*(BOM!$N$2:$N$71="USD")*BOM!$H$2:$H$71*(1+BOM!$I$2:$I$71)*BOM!$M$2:$M$71) -> 0 | K2: =SUM(E2,G2,I2) -> 174803.39 | L2: =SUM(F2,H2,J2) -> 0 | M2: =IFERROR(K2/D2,0) -> 33.21364 | N2: =IFERROR(L2/D2,0) -> 0
A3: EST-0002 | B3: =Order_Sheet!A3 -> SO-2026-0002 | C3: =Order_Sheet!D3 -> ST-109 | D3: =Order_Sheet!F3 -> 9914 | E3: =D3*SUMPRODUCT((BOM!$B$2:$B$71=C3)*(BOM!$E$2:$E$71="Fabric")*(BOM!$N$2:$N$71="BDT")*BOM!$H$2:$H$71*(1+BOM!$I$2:$I$71)*BOM!$M$2:$M$71) -> 64942.462 | F3: =D3*SUMPRODUCT((BOM!$B$2:$B$71=C3)*(BOM!$E$2:$E$71="Fabric")*(BOM!$N$2:$N$71="USD")*BOM!$H$2:$H$71*(1+BOM!$I$2:$I$71)*BOM!$M$2:$M$71) -> 0 | G3: =D3*SUMPRODUCT((BOM!$B$2:$B$71=C3)*(BOM!$E$2:$E$71="Accessory")*(BOM!$N$2:$N$71="BDT")*BOM!$H$2:$H$71*(1+BOM!$I$2:$I$71)*BOM!$M$2:$M$71) -> 195700.87 | H3: =D3*SUMPRODUCT((BOM!$B$2:$B$71=C3)*(BOM!$E$2:$E$71="Accessory")*(BOM!$N$2:$N$71="USD")*BOM!$H$2:$H$71*(1+BOM!$I$2:$I$71)*BOM!$M$2:$M$71) -> 0 | I3: =D3*SUMPRODUCT((BOM!$B$2:$B$71=C3)*(BOM!$E$2:$E$71="Packing")*(BOM!$N$2:$N$71="BDT")*BOM!$H$2:$H$71*(1+BOM!$I$2:$I$71)*BOM!$M$2:$M$71) -> 280.3471 | J3: =D3*SUMPRODUCT((BOM!$B$2:$B$71=C3)*(BOM!$E$2:$E$71="Packing")*(BOM!$N$2:$N$71="USD")*BOM!$H$2:$H$71*(1+BOM!$I$2:$I$71)*BOM!$M$2:$M$71) -> 0 | K3: =SUM(E3,G3,I3) -> 260923.68 | L3: =SUM(F3,H3,J3) -> 0 | M3: =IFERROR(K3/D3,0) -> 26.318709 | N3: =IFERROR(L3/D3,0) -> 0
A4: EST-0003 | B4: =Order_Sheet!A4 -> SO-2026-0003 | C4: =Order_Sheet!D4 -> ST-108 | D4: =Order_Sheet!F4 -> 1342 | E4: =D4*SUMPRODUCT((BOM!$B$2:$B$71=C4)*(BOM!$E$2:$E$71="Fabric")*(BOM!$N$2:$N$71="BDT")*BOM!$H$2:$H$71*(1+BOM!$I$2:$I$71)*BOM!$M$2:$M$71) -> 1985.9142 | F4: =D4*SUMPRODUCT((BOM!$B$2:$B$71=C4)*(BOM!$E$2:$E$71="Fabric")*(BOM!$N$2:$N$71="USD")*BOM!$H$2:$H$71*(1+BOM!$I$2:$I$71)*BOM!$M$2:$M$71) -> 588.57468 | G4: =D4*SUMPRODUCT((BOM!$B$2:$B$71=C4)*(BOM!$E$2:$E$71="Accessory")*(BOM!$N$2:$N$71="BDT")*BOM!$H$2:$H$71*(1+BOM!$I$2:$I$71)*BOM!$M$2:$M$71) -> 56507.643 | H4: =D4*SUMPRODUCT((BOM!$B$2:$B$71=C4)*(BOM!$E$2:$E$71="Accessory")*(BOM!$N$2:$N$71="USD")*BOM!$H$2:$H$71*(1+BOM!$I$2:$I$71)*BOM!$M$2:$M$71) -> 0 | I4: =D4*SUMPRODUCT((BOM!$B$2:$B$71=C4)*(BOM!$E$2:$E$71="Packing")*(BOM!$N$2:$N$71="BDT")*BOM!$H$2:$H$71*(1+BOM!$I$2:$I$71)*BOM!$M$2:$M$71) -> 554.70872 | J4: =D4*SUMPRODUCT((BOM!$B$2:$B$71=C4)*(BOM!$E$2:$E$71="Packing")*(BOM!$N$2:$N$71="USD")*BOM!$H$2:$H$71*(1+BOM!$I$2:$I$71)*BOM!$M$2:$M$71) -> 0 | K4: =SUM(E4,G4,I4) -> 59048.266 | L4: =SUM(F4,H4,J4) -> 588.57468 | M4: =IFERROR(K4/D4,0) -> 44.000198 | N4: =IFERROR(L4/D4,0) -> 0.43858024
A5: EST-0004 | B5: =Order_Sheet!A5 -> SO-2026-0004 | C5: =Order_Sheet!D5 -> ST-110 | D5: =Order_Sheet!F5 -> 5769 | E5: =D5*SUMPRODUCT((BOM!$B$2:$B$71=C5)*(BOM!$E$2:$E$71="Fabric")*(BOM!$N$2:$N$71="BDT")*BOM!$H$2:$H$71*(1+BOM!$I$2:$I$71)*BOM!$M$2:$M$71) -> 46483.596 | F5: =D5*SUMPRODUCT((BOM!$B$2:$B$71=C5)*(BOM!$E$2:$E$71="Fabric")*(BOM!$N$2:$N$71="USD")*BOM!$H$2:$H$71*(1+BOM!$I$2:$I$71)*BOM!$M$2:$M$71) -> 0 | G5: =D5*SUMPRODUCT((BOM!$B$2:$B$71=C5)*(BOM!$E$2:$E$71="Accessory")*(BOM!$N$2:$N$71="BDT")*BOM!$H$2:$H$71*(1+BOM!$I$2:$I$71)*BOM!$M$2:$M$71) -> 117457.62 | H5: =D5*SUMPRODUCT((BOM!$B$2:$B$71=C5)*(BOM!$E$2:$E$71="Accessory")*(BOM!$N$2:$N$71="USD")*BOM!$H$2:$H$71*(1+BOM!$I$2:$I$71)*BOM!$M$2:$M$71) -> 0 | I5: =D5*SUMPRODUCT((BOM!$B$2:$B$71=C5)*(BOM!$E$2:$E$71="Packing")*(BOM!$N$2:$N$71="BDT")*BOM!$H$2:$H$71*(1+BOM!$I$2:$I$71)*BOM!$M$2:$M$71) -> 22432.576 | J5: =D5*SUMPRODUCT((BOM!$B$2:$B$71=C5)*(BOM!$E$2:$E$71="Packing")*(BOM!$N$2:$N$71="USD")*BOM!$H$2:$H$71*(1+BOM!$I$2:$I$71)*BOM!$M$2:$M$71) -> 0 | K5: =SUM(E5,G5,I5) -> 186373.79 | L5: =SUM(F5,H5,J5) -> 0 | M5: =IFERROR(K5/D5,0) -> 32.306082 | N5: =IFERROR(L5/D5,0) -> 0
A6: EST-0005 | B6: =Order_Sheet!A6 -> SO-2026-0005 | C6: =Order_Sheet!D6 -> ST-101 | D6: =Order_Sheet!F6 -> 11218 | E6: =D6*SUMPRODUCT((BOM!$B$2:$B$71=C6)*(BOM!$E$2:$E$71="Fabric")*(BOM!$N$2:$N$71="BDT")*BOM!$H$2:$H$71*(1+BOM!$I$2:$I$71)*BOM!$M$2:$M$71) -> 21892.198 | F6: =D6*SUMPRODUCT((BOM!$B$2:$B$71=C6)*(BOM!$E$2:$E$71="Fabric")*(BOM!$N$2:$N$71="USD")*BOM!$H$2:$H$71*(1+BOM!$I$2:$I$71)*BOM!$M$2:$M$71) -> 3998.7364 | G6: =D6*SUMPRODUCT((BOM!$B$2:$B$71=C6)*(BOM!$E$2:$E$71="Accessory")*(BOM!$N$2:$N$71="BDT")*BOM!$H$2:$H$71*(1+BOM!$I$2:$I$71)*BOM!$M$2:$M$71) -> 329173.91 | H6: =D6*SUMPRODUCT((BOM!$B$2:$B$71=C6)*(BOM!$E$2:$E$71="Accessory")*(BOM!$N$2:$N$71="USD")*BOM!$H$2:$H$71*(1+BOM!$I$2:$I$71)*BOM!$M$2:$M$71) -> 0 | I6: =D6*SUMPRODUCT((BOM!$B$2:$B$71=C6)*(BOM!$E$2:$E$71="Packing")*(BOM!$N$2:$N$71="BDT")*BOM!$H$2:$H$71*(1+BOM!$I$2:$I$71)*BOM!$M$2:$M$71) -> 20353.855 | J6: =D6*SUMPRODUCT((BOM!$B$2:$B$71=C6)*(BOM!$E$2:$E$71="Packing")*(BOM!$N$2:$N$71="USD")*BOM!$H$2:$H$71*(1+BOM!$I$2:$I$71)*BOM!$M$2:$M$71) -> 0 | K6: =SUM(E6,G6,I6) -> 371419.96 | L6: =SUM(F6,H6,J6) -> 3998.7364 | M6: =IFERROR(K6/D6,0) -> 33.109285 | N6: =IFERROR(L6/D6,0) -> 0.35645716
A7: EST-0006 | B7: =Order_Sheet!A7 -> SO-2026-0006 | C7: =Order_Sheet!D7 -> ST-105 | D7: =Order_Sheet!F7 -> 4306 | E7: =D7*SUMPRODUCT((BOM!$B$2:$B$71=C7)*(BOM!$E$2:$E$71="Fabric")*(BOM!$N$2:$N$71="BDT")*BOM!$H$2:$H$71*(1+BOM!$I$2:$I$71)*BOM!$M$2:$M$71) -> 16750.799 | F7: =D7*SUMPRODUCT((BOM!$B$2:$B$71=C7)*(BOM!$E$2:$E$71="Fabric")*(BOM!$N$2:$N$71="USD")*BOM!$H$2:$H$71*(1+BOM!$I$2:$I$71)*BOM!$M$2:$M$71) -> 0 | G7: =D7*SUMPRODUCT((BOM!$B$2:$B$71=C7)*(BOM!$E$2:$E$71="Accessory")*(BOM!$N$2:$N$71="BDT")*BOM!$H$2:$H$71*(1+BOM!$I$2:$I$71)*BOM!$M$2:$M$71) -> 219911.66 | H7: =D7*SUMPRODUCT((BOM!$B$2:$B$71=C7)*(BOM!$E$2:$E$71="Accessory")*(BOM!$N$2:$N$71="USD")*BOM!$H$2:$H$71*(1+BOM!$I$2:$I$71)*BOM!$M$2:$M$71) -> 0 | I7: =D7*SUMPRODUCT((BOM!$B$2:$B$71=C7)*(BOM!$E$2:$E$71="Packing")*(BOM!$N$2:$N$71="BDT")*BOM!$H$2:$H$71*(1+BOM!$I$2:$I$71)*BOM!$M$2:$M$71) -> 5342.2331 | J7: =D7*SUMPRODUCT((BOM!$B$2:$B$71=C7)*(BOM!$E$2:$E$71="Packing")*(BOM!$N$2:$N$71="USD")*BOM!$H$2:$H$71*(1+BOM!$I$2:$I$71)*BOM!$M$2:$M$71) -> 0 | K7: =SUM(E7,G7,I7) -> 242004.69 | L7: =SUM(F7,H7,J7) -> 0 | M7: =IFERROR(K7/D7,0) -> 56.20174 | N7: =IFERROR(L7/D7,0) -> 0
A8: EST-0007 | B8: =Order_Sheet!A8 -> SO-2026-0007 | C8: =Order_Sheet!D8 -> ST-107 | D8: =Order_Sheet!F8 -> 4961 | E8: =D8*SUMPRODUCT((BOM!$B$2:$B$71=C8)*(BOM!$E$2:$E$71="Fabric")*(BOM!$N$2:$N$71="BDT")*BOM!$H$2:$H$71*(1+BOM!$I$2:$I$71)*BOM!$M$2:$M$71) -> 42747.705 | F8: =D8*SUMPRODUCT((BOM!$B$2:$B$71=C8)*(BOM!$E$2:$E$71="Fabric")*(BOM!$N$2:$N$71="USD")*BOM!$H$2:$H$71*(1+BOM!$I$2:$I$71)*BOM!$M$2:$M$71) -> 0 | G8: =D8*SUMPRODUCT((BOM!$B$2:$B$71=C8)*(BOM!$E$2:$E$71="Accessory")*(BOM!$N$2:$N$71="BDT")*BOM!$H$2:$H$71*(1+BOM!$I$2:$I$71)*BOM!$M$2:$M$71) -> 144680.53 | H8: =D8*SUMPRODUCT((BOM!$B$2:$B$71=C8)*(BOM!$E$2:$E$71="Accessory")*(BOM!$N$2:$N$71="USD")*BOM!$H$2:$H$71*(1+BOM!$I$2:$I$71)*BOM!$M$2:$M$71) -> 0 | I8: =D8*SUMPRODUCT((BOM!$B$2:$B$71=C8)*(BOM!$E$2:$E$71="Packing")*(BOM!$N$2:$N$71="BDT")*BOM!$H$2:$H$71*(1+BOM!$I$2:$I$71)*BOM!$M$2:$M$71) -> 5120.392 | J8: =D8*SUMPRODUCT((BOM!$B$2:$B$71=C8)*(BOM!$E$2:$E$71="Packing")*(BOM!$N$2:$N$71="USD")*BOM!$H$2:$H$71*(1+BOM!$I$2:$I$71)*BOM!$M$2:$M$71) -> 0 | K8: =SUM(E8,G8,I8) -> 192548.63 | L8: =SUM(F8,H8,J8) -> 0 | M8: =IFERROR(K8/D8,0) -> 38.812463 | N8: =IFERROR(L8/D8,0) -> 0
A9: EST-0008 | B9: =Order_Sheet!A9 -> SO-2026-0008 | C9: =Order_Sheet!D9 -> ST-102 | D9: =Order_Sheet!F9 -> 9075 | E9: =D9*SUMPRODUCT((BOM!$B$2:$B$71=C9)*(BOM!$E$2:$E$71="Fabric")*(BOM!$N$2:$N$71="BDT")*BOM!$H$2:$H$71*(1+BOM!$I$2:$I$71)*BOM!$M$2:$M$71) -> 46072.148 | F9: =D9*SUMPRODUCT((BOM!$B$2:$B$71=C9)*(BOM!$E$2:$E$71="Fabric")*(BOM!$N$2:$N$71="USD")*BOM!$H$2:$H$71*(1+BOM!$I$2:$I$71)*BOM!$M$2:$M$71) -> 0 | G9: =D9*SUMPRODUCT((BOM!$B$2:$B$71=C9)*(BOM!$E$2:$E$71="Accessory")*(BOM!$N$2:$N$71="BDT")*BOM!$H$2:$H$71*(1+BOM!$I$2:$I$71)*BOM!$M$2:$M$71) -> 122921.23 | H9: =D9*SUMPRODUCT((BOM!$B$2:$B$71=C9)*(BOM!$E$2:$E$71="Accessory")*(BOM!$N$2:$N$71="USD")*BOM!$H$2:$H$71*(1+BOM!$I$2:$I$71)*BOM!$M$2:$M$71) -> 0 | I9: =D9*SUMPRODUCT((BOM!$B$2:$B$71=C9)*(BOM!$E$2:$E$71="Packing")*(BOM!$N$2:$N$71="BDT")*BOM!$H$2:$H$71*(1+BOM!$I$2:$I$71)*BOM!$M$2:$M$71) -> 4092.4517 | J9: =D9*SUMPRODUCT((BOM!$B$2:$B$71=C9)*(BOM!$E$2:$E$71="Packing")*(BOM!$N$2:$N$71="USD")*BOM!$H$2:$H$71*(1+BOM!$I$2:$I$71)*BOM!$M$2:$M$71) -> 0 | K9: =SUM(E9,G9,I9) -> 173085.83 | L9: =SUM(F9,H9,J9) -> 0 | M9: =IFERROR(K9/D9,0) -> 19.072819 | N9: =IFERROR(L9/D9,0) -> 0
A10: EST-0009 | B10: =Order_Sheet!A10 -> SO-2026-0009 | C10: =Order_Sheet!D10 -> ST-109 | D10: =Order_Sheet!F10 -> 2613 | E10: =D10*SUMPRODUCT((BOM!$B$2:$B$71=C10)*(BOM!$E$2:$E$71="Fabric")*(BOM!$N$2:$N$71="BDT")*BOM!$H$2:$H$71*(1+BOM!$I$2:$I$71)*BOM!$M$2:$M$71) -> 17116.669 | F10: =D10*SUMPRODUCT((BOM!$B$2:$B$71=C10)*(BOM!$E$2:$E$71="Fabric")*(BOM!$N$2:$N$71="USD")*BOM!$H$2:$H$71*(1+BOM!$I$2:$I$71)*BOM!$M$2:$M$71) -> 0 | G10: =D10*SUMPRODUCT((BOM!$B$2:$B$71=C10)*(BOM!$E$2:$E$71="Accessory")*(BOM!$N$2:$N$71="BDT")*BOM!$H$2:$H$71*(1+BOM!$I$2:$I$71)*BOM!$M$2:$M$71) -> 51580.228 | H10: =D10*SUMPRODUCT((BOM!$B$2:$B$71=C10)*(BOM!$E$2:$E$71="Accessory")*(BOM!$N$2:$N$71="USD")*BOM!$H$2:$H$71*(1+BOM!$I$2:$I$71)*BOM!$M$2:$M$71) -> 0 | I10: =D10*SUMPRODUCT((BOM!$B$2:$B$71=C10)*(BOM!$E$2:$E$71="Packing")*(BOM!$N$2:$N$71="BDT")*BOM!$H$2:$H$71*(1+BOM!$I$2:$I$71)*BOM!$M$2:$M$71) -> 73.890153 | J10: =D10*SUMPRODUCT((BOM!$B$2:$B$71=C10)*(BOM!$E$2:$E$71="Packing")*(BOM!$N$2:$N$71="USD")*BOM!$H$2:$H$71*(1+BOM!$I$2:$I$71)*BOM!$M$2:$M$71) -> 0 | K10: =SUM(E10,G10,I10) -> 68770.787 | L10: =SUM(F10,H10,J10) -> 0 | M10: =IFERROR(K10/D10,0) -> 26.318709 | N10: =IFERROR(L10/D10,0) -> 0
A11: EST-0010 | B11: =Order_Sheet!A11 -> SO-2026-0010 | C11: =Order_Sheet!D11 -> ST-105 | D11: =Order_Sheet!F11 -> 5933 | E11: =D11*SUMPRODUCT((BOM!$B$2:$B$71=C11)*(BOM!$E$2:$E$71="Fabric")*(BOM!$N$2:$N$71="BDT")*BOM!$H$2:$H$71*(1+BOM!$I$2:$I$71)*BOM!$M$2:$M$71) -> 23080.002 | F11: =D11*SUMPRODUCT((BOM!$B$2:$B$71=C11)*(BOM!$E$2:$E$71="Fabric")*(BOM!$N$2:$N$71="USD")*BOM!$H$2:$H$71*(1+BOM!$I$2:$I$71)*BOM!$M$2:$M$71) -> 0 | G11: =D11*SUMPRODUCT((BOM!$B$2:$B$71=C11)*(BOM!$E$2:$E$71="Accessory")*(BOM!$N$2:$N$71="BDT")*BOM!$H$2:$H$71*(1+BOM!$I$2:$I$71)*BOM!$M$2:$M$71) -> 303004.15 | H11: =D11*SUMPRODUCT((BOM!$B$2:$B$71=C11)*(BOM!$E$2:$E$71="Accessory")*(BOM!$N$2:$N$71="USD")*BOM!$H$2:$H$71*(1+BOM!$I$2:$I$71)*BOM!$M$2:$M$71) -> 0 | I11: =D11*SUMPRODUCT((BOM!$B$2:$B$71=C11)*(BOM!$E$2:$E$71="Packing")*(BOM!$N$2:$N$71="BDT")*BOM!$H$2:$H$71*(1+BOM!$I$2:$I$71)*BOM!$M$2:$M$71) -> 7360.7684 | J11: =D11*SUMPRODUCT((BOM!$B$2:$B$71=C11)*(BOM!$E$2:$E$71="Packing")*(BOM!$N$2:$N$71="USD")*BOM!$H$2:$H$71*(1+BOM!$I$2:$I$71)*BOM!$M$2:$M$71) -> 0 | K11: =SUM(E11,G11,I11) -> 333444.92 | L11: =SUM(F11,H11,J11) -> 0 | M11: =IFERROR(K11/D11,0) -> 56.20174 | N11: =IFERROR(L11/D11,0) -> 0
A12: EST-0011 | B12: =Order_Sheet!A12 -> SO-2026-0011 | C12: =Order_Sheet!D12 -> ST-107 | D12: =Order_Sheet!F12 -> 3043 | E12: =D12*SUMPRODUCT((BOM!$B$2:$B$71=C12)*(BOM!$E$2:$E$71="Fabric")*(BOM!$N$2:$N$71="BDT")*BOM!$H$2:$H$71*(1+BOM!$I$2:$I$71)*BOM!$M$2:$M$71) -> 26220.776 | F12: =D12*SUMPRODUCT((BOM!$B$2:$B$71=C12)*(BOM!$E$2:$E$71="Fabric")*(BOM!$N$2:$N$71="USD")*BOM!$H$2:$H$71*(1+BOM!$I$2:$I$71)*BOM!$M$2:$M$71) -> 0 | G12: =D12*SUMPRODUCT((BOM!$B$2:$B$71=C12)*(BOM!$E$2:$E$71="Accessory")*(BOM!$N$2:$N$71="BDT")*BOM!$H$2:$H$71*(1+BOM!$I$2:$I$71)*BOM!$M$2:$M$71) -> 88744.781 | H12: =D12*SUMPRODUCT((BOM!$B$2:$B$71=C12)*(BOM!$E$2:$E$71="Accessory")*(BOM!$N$2:$N$71="USD")*BOM!$H$2:$H$71*(1+BOM!$I$2:$I$71)*BOM!$M$2:$M$71) -> 0 | I12: =D12*SUMPRODUCT((BOM!$B$2:$B$71=C12)*(BOM!$E$2:$E$71="Packing")*(BOM!$N$2:$N$71="BDT")*BOM!$H$2:$H$71*(1+BOM!$I$2:$I$71)*BOM!$M$2:$M$71) -> 3140.7685 | J12: =D12*SUMPRODUCT((BOM!$B$2:$B$71=C12)*(BOM!$E$2:$E$71="Packing")*(BOM!$N$2:$N$71="USD")*BOM!$H$2:$H$71*(1+BOM!$I$2:$I$71)*BOM!$M$2:$M$71) -> 0 | K12: =SUM(E12,G12,I12) -> 118106.33 | L12: =SUM(F12,H12,J12) -> 0 | M12: =IFERROR(K12/D12,0) -> 38.812463 | N12: =IFERROR(L12/D12,0) -> 0
A13: EST-0012 | B13: =Order_Sheet!A13 -> SO-2026-0012 | C13: =Order_Sheet!D13 -> ST-102 | D13: =Order_Sheet!F13 -> 7152 | E13: =D13*SUMPRODUCT((BOM!$B$2:$B$71=C13)*(BOM!$E$2:$E$71="Fabric")*(BOM!$N$2:$N$71="BDT")*BOM!$H$2:$H$71*(1+BOM!$I$2:$I$71)*BOM!$M$2:$M$71) -> 36309.422 | F13: =D13*SUMPRODUCT((BOM!$B$2:$B$71=C13)*(BOM!$E$2:$E$71="Fabric")*(BOM!$N$2:$N$71="USD")*BOM!$H$2:$H$71*(1+BOM!$I$2:$I$71)*BOM!$M$2:$M$71) -> 0 | G13: =D13*SUMPRODUCT((BOM!$B$2:$B$71=C13)*(BOM!$E$2:$E$71="Accessory")*(BOM!$N$2:$N$71="BDT")*BOM!$H$2:$H$71*(1+BOM!$I$2:$I$71)*BOM!$M$2:$M$71) -> 96874.123 | H13: =D13*SUMPRODUCT((BOM!$B$2:$B$71=C13)*(BOM!$E$2:$E$71="Accessory")*(BOM!$N$2:$N$71="USD")*BOM!$H$2:$H$71*(1+BOM!$I$2:$I$71)*BOM!$M$2:$M$71) -> 0 | I13: =D13*SUMPRODUCT((BOM!$B$2:$B$71=C13)*(BOM!$E$2:$E$71="Packing")*(BOM!$N$2:$N$71="BDT")*BOM!$H$2:$H$71*(1+BOM!$I$2:$I$71)*BOM!$M$2:$M$71) -> 3225.2578 | J13: =D13*SUMPRODUCT((BOM!$B$2:$B$71=C13)*(BOM!$E$2:$E$71="Packing")*(BOM!$N$2:$N$71="USD")*BOM!$H$2:$H$71*(1+BOM!$I$2:$I$71)*BOM!$M$2:$M$71) -> 0 | K13: =SUM(E13,G13,I13) -> 136408.8 | L13: =SUM(F13,H13,J13) -> 0 | M13: =IFERROR(K13/D13,0) -> 19.072819 | N13: =IFERROR(L13/D13,0) -> 0
... A81: EST-0080 | B81: =Order_Sheet!A81 -> SO-2026-0080 | C81: =Order_Sheet!D81 -> ST-110 | D81: =Order_Sheet!F81 -> 1732 | E81: =D81*SUMPRODUCT((BOM!$B$2:$B$71=C81)*(BOM!$E$2:$E$71="Fabric")*(BOM!$N$2:$N$71="BDT")*BOM!$H$2:$H$71*(1+BOM!$I$2:$I$71)*BOM!$M$2:$M$71) -> 13955.553 | F81: =D81*SUMPRODUCT((BOM!$B$2:$B$71=C81)*(BOM!$E$2:$E$71="Fabric")*(BOM!$N$2:$N$71="USD")*BOM!$H$2:$H$71*(1+BOM!$I$2:$I$71)*BOM!$M$2:$M$71) -> 0 | G81: =D81*SUMPRODUCT((BOM!$B$2:$B$71=C81)*(BOM!$E$2:$E$71="Accessory")*(BOM!$N$2:$N$71="BDT")*BOM!$H$2:$H$71*(1+BOM!$I$2:$I$71)*BOM!$M$2:$M$71) -> 35263.753 | H81: =D81*SUMPRODUCT((BOM!$B$2:$B$71=C81)*(BOM!$E$2:$E$71="Accessory")*(BOM!$N$2:$N$71="USD")*BOM!$H$2:$H$71*(1+BOM!$I$2:$I$71)*BOM!$M$2:$M$71) -> 0 | I81: =D81*SUMPRODUCT((BOM!$B$2:$B$71=C81)*(BOM!$E$2:$E$71="Packing")*(BOM!$N$2:$N$71="BDT")*BOM!$H$2:$H$71*(1+BOM!$I$2:$I$71)*BOM!$M$2:$M$71) -> 6734.8279 | J81: =D81*SUMPRODUCT((BOM!$B$2:$B$71=C81)*(BOM!$E$2:$E$71="Packing")*(BOM!$N$2:$N$71="USD")*BOM!$H$2:$H$71*(1+BOM!$I$2:$I$71)*BOM!$M$2:$M$71) -> 0 | K81: =SUM(E81,G81,I81) -> 55954.134 | L81: =SUM(F81,H81,J81) -> 0 | M81: =IFERROR(K81/D81,0) -> 32.306082 | N81: =IFERROR(L81/D81,0) -> 0

Sheet PO_Tracker
A1: PO_No | B1: PO_Date | C1: Order_No | D1: Style | E1: Purchase_Type | F1: Supplier | G1: Item_Code | H1: Item_Type | I1: Qty | J1: UOM | K1: Unit_Price | L1: Currency | M1: Status | N1: Data_Check
A2: PO-2026-00001 | B2: 46048 | C2: SO-2026-0049 | D2: ST-105 | E2: Local | F2: Delta Textiles | G2: ACC-0105 | H2: Accessory | I2: 55331 | J2: PCS | K2: 1 | L2: USD | M2: Received | N2: =IF(COUNTA(A2:M2)<13,"MISSING DATA",IF(OR(I2<=0,K2<=0),"VALUE ERROR","OK")) -> OK
A3: PO-2026-00002 | B3: 46092 | C3: SO-2026-0035 | D3: ST-110 | E3: Local | F3: Prime Accessories | G3: ACC-0101 | H3: Accessory | I3: 42397 | J3: PCS | K3: 1 | L3: USD | M3: Received | N3: =IF(COUNTA(A3:M3)<13,"MISSING DATA",IF(OR(I3<=0,K3<=0),"VALUE ERROR","OK")) -> OK
A4: PO-2026-00003 | B4: 46129 | C4: SO-2026-0073 | D4: ST-104 | E4: Local | F4: Global Fabrics Ltd. | G4: ACC-0117 | H4: Accessory | I4: 34942 | J4: MTR | K4: 1 | L4: USD | M4: Open | N4: =IF(COUNTA(A4:M4)<13,"MISSING DATA",IF(OR(I4<=0,K4<=0),"VALUE ERROR","OK")) -> OK
A5: PO-2026-00004 | B5: 46097 | C5: SO-2026-0027 | D5: ST-102 | E5: Local | F5: Metro Trims | G5: ACC-0104 | H5: Accessory | I5: 36015 | J5: PCS | K5: 1.65 | L5: BDT | M5: Partial | N5: =IF(COUNTA(A5:M5)<13,"MISSING DATA",IF(OR(I5<=0,K5<=0),"VALUE ERROR","OK")) -> OK
A6: PO-2026-00005 | B6: 46079 | C6: SO-2026-0002 | D6: ST-109 | E6: Local | F6: Sunrise Packing | G6: ACC-0123 | H6: Accessory | I6: 11809 | J6: PCS | K6: 1 | L6: USD | M6: Open | N6: =IF(COUNTA(A6:M6)<13,"MISSING DATA",IF(OR(I6<=0,K6<=0),"VALUE ERROR","OK")) -> OK
A7: PO-2026-00006 | B7: 46053 | C7: SO-2026-0060 | D7: ST-107 | E7: Local | F7: Prime Accessories | G7: ACC-0101 | H7: Accessory | I7: 33813 | J7: PCS | K7: 1 | L7: USD | M7: Open | N7: =IF(COUNTA(A7:M7)<13,"MISSING DATA",IF(OR(I7<=0,K7<=0),"VALUE ERROR","OK")) -> OK
A8: PO-2026-00007 | B8: 46106 | C8: SO-2026-0001 | D8: ST-103 | E8: Foreign | F8: Delta Textiles | G8: FAB-0110 | H8: Fabric | I8: 3058 | J8: KG | K8: 1 | L8: USD | M8: Partial | N8: =IF(COUNTA(A8:M8)<13,"MISSING DATA",IF(OR(I8<=0,K8<=0),"VALUE ERROR","OK")) -> OK
A9: PO-2026-00008 | B9: 46044 | C9: SO-2026-0076 | D9: ST-108 | E9: Local | F9: Delta Textiles | G9: PKG-0118 | H9: Packing | I9: 4236 | J9: PCS | K9: 3.19 | L9: BDT | M9: Received | N9: =IF(COUNTA(A9:M9)<13,"MISSING DATA",IF(OR(I9<=0,K9<=0),"VALUE ERROR","OK")) -> OK
A10: PO-2026-00009 | B10: 46087 | C10: SO-2026-0074 | D10: ST-104 | E10: Local | F10: Sunrise Packing | G10: ACC-0133 | H10: Accessory | I10: 30342 | J10: CONE | K10: 3.06 | L10: BDT | M10: Open | N10: =IF(COUNTA(A10:M10)<13,"MISSING DATA",IF(OR(I10<=0,K10<=0),"VALUE ERROR","OK")) -> OK
A11: PO-2026-00010 | B11: 46040 | C11: SO-2026-0070 | D11: ST-104 | E11: Local | F11: Sunrise Packing | G11: ACC-0133 | H11: Accessory | I11: 32099 | J11: CONE | K11: 3.06 | L11: BDT | M11: Received | N11: =IF(COUNTA(A11:M11)<13,"MISSING DATA",IF(OR(I11<=0,K11<=0),"VALUE ERROR","OK")) -> OK
A12: PO-2026-00011 | B12: 46081 | C12: SO-2026-0039 | D12: ST-104 | E12: Foreign | F12: Delta Textiles | G12: FAB-0110 | H12: Fabric | I12: 2617 | J12: KG | K12: 1 | L12: USD | M12: Received | N12: =IF(COUNTA(A12:M12)<13,"MISSING DATA",IF(OR(I12<=0,K12<=0),"VALUE ERROR","OK")) -> OK
A13: PO-2026-00012 | B13: 46112 | C13: SO-2026-0033 | D13: ST-102 | E13: Local | F13: Metro Trims | G13: FAB-0115 | H13: Fabric | I13: 4713 | J13: KG | K13: 5.15 | L13: BDT | M13: Partial | N13: =IF(COUNTA(A13:M13)<13,"MISSING DATA",IF(OR(I13<=0,K13<=0),"VALUE ERROR","OK")) -> OK
... A181: PO-2026-00180 | B181: 46120 | C181: SO-2026-0073 | D181: ST-104 | E181: Local | F181: Global Fabrics Ltd. | G181: PKG-0107 | H181: Packing | I181: 2793 | J181: PCS | K181: 1 | L181: USD | M181: Open | N181: =IF(COUNTA(A181:M181)<13,"MISSING DATA",IF(OR(I181<=0,K181<=0),"VALUE ERROR","OK")) -> OK

Sheet Cost_Sheet
A1: Style | B1: Order_No | C1: Qty | D1: Fabric_Cost | E1: Accessories_Cost | F1: Packing_Cost | G1: Labor_Cost | H1: Overhead | I1: Total_Cost | J1: Cost_per_Piece
A2: SO-2026-0001 | B2: ST-103 | C2: 5263 | D2: 9901.47 | E2: 6026.58 | F2: 1139.14 | G2: 10005.71 | H2: 3562.27 | I2: =SUM(D2:H2) -> 30635.17 | J2: =IFERROR(I2/C2,0) -> 5.8208569
A3: SO-2026-0002 | B3: ST-109 | C3: 9914 | D3: 35120.48 | E3: 13418.6 | F3: 1610.6 | G3: 8685.87 | H3: 2776.49 | I3: =SUM(D3:H3) -> 61612.04 | J3: =IFERROR(I3/C3,0) -> 6.21465
A4: SO-2026-0003 | B4: ST-108 | C4: 1342 | D4: 4480.25 | E4: 885.8 | F4: 217.26 | G4: 2702.53 | H4: 198.66 | I4: =SUM(D4:H4) -> 8484.5 | J4: =IFERROR(I4/C4,0) -> 6.3222802
A5: SO-2026-0004 | B5: ST-110 | C5: 5769 | D5: 20555.11 | E5: 5002.32 | F5: 848.26 | G5: 10288.47 | H5: 2689.45 | I5: =SUM(D5:H5) -> 39383.61 | J5: =IFERROR(I5/C5,0) -> 6.8267655
A6: SO-2026-0005 | B6: ST-101 | C6: 11218 | D6: 44055.11 | E6: 4371.27 | F6: 2589.4 | G6: 22515.03 | H6: 6307.52 | I6: =SUM(D6:H6) -> 79838.33 | J6: =IFERROR(I6/C6,0) -> 7.1169843
A7: SO-2026-0006 | B7: ST-105 | C7: 4306 | D7: 12594.5 | E7: 4838.32 | F7: 1690.57 | G7: 8718.14 | H7: 1628.77 | I7: =SUM(D7:H7) -> 29470.3 | J7: =IFERROR(I7/C7,0) -> 6.8440084
A8: SO-2026-0007 | B8: ST-107 | C8: 4961 | D8: 9854.09 | E8: 3551.38 | F8: 1961 | G8: 7848.51 | H8: 2630.2 | I8: =SUM(D8:H8) -> 25845.18 | J8: =IFERROR(I8/C8,0) -> 5.2096714
A9: SO-2026-0008 | B9: ST-102 | C9: 9075 | D9: 11902.21 | E9: 4806.66 | F9: 1219.53 | G9: 12675.4 | H9: 3160.97 | I9: =SUM(D9:H9) -> 33764.77 | J9: =IFERROR(I9/C9,0) -> 3.7206358
A10: SO-2026-0009 | B10: ST-109 | C10: 2613 | D10: 7453.29 | E10: 1277.11 | F10: 167.66 | G10: 1580.61 | H10: 905.62 | I10: =SUM(D10:H10) -> 11384.29 | J10: =IFERROR(I10/C10,0) -> 4.3567891
A11: SO-2026-0010 | B11: ST-105 | C11: 5933 | D11: 7708.09 | E11: 3409.19 | F11: 1897.84 | G11: 11077.71 | H11: 1403.33 | I11: =SUM(D11:H11) -> 25496.16 | J11: =IFERROR(I11/C11,0) -> 4.297347
A12: SO-2026-0011 | B12: ST-107 | C12: 3043 | D12: 6389.82 | E12: 3992.03 | F12: 470.03 | G12: 6005.89 | H12: 447.5 | I12: =SUM(D12:H12) -> 17305.27 | J12: =IFERROR(I12/C12,0) -> 5.6869109
A13: SO-2026-0012 | B13: ST-102 | C13: 7152 | D13: 12398.75 | E13: 5900.75 | F13: 2268.21 | G13: 16227.47 | H13: 998.65 | I13: =SUM(D13:H13) -> 37793.83 | J13: =IFERROR(I13/C13,0) -> 5.2843722
... A81: SO-2026-0080 | B81: ST-110 | C81: 1732 | D81: 2630.08 | E81: 2556.17 | F81: 97.91 | G81: 3906.3 | H81: 939.84 | I81: =SUM(D81:H81) -> 10130.3 | J81: =IFERROR(I81/C81,0) -> 5.848903

Sheet Accuracy_Check
A1: Order_No | B1: Order_Qty | C1: PO_Qty | D1: Cost_Qty | E1: Qty_Check | F1: Style_Check | G1: Currency_Check | H1: Overall_Status | I1: Action
A2: =Order_Sheet!A2 -> SO-2026-0001 | B2: =IFERROR(VLOOKUP(A2,Order_Sheet!A:L,6,FALSE),"") -> 5263 | C2: =IFERROR(SUMIF(PO_Tracker!C:C,A2,PO_Tracker!I:I),"") -> 3058 | D2: =IFERROR(VLOOKUP(A2,Cost_Sheet!B:J,2,FALSE),"") | E2: =IF(OR(B2="",C2=""),"CHECK",IF(ABS(B2-C2)<=B2*5%,"OK","QTY MISMATCH")) -> QTY MISMATCH | F2: =IFERROR(IF(VLOOKUP(A2,Order_Sheet!A:L,4,FALSE)=INDEX(PO_Tracker!D:D,MATCH(A2,PO_Tracker!C:C,0)),"OK","STYLE MISMATCH"),"CHECK") -> OK | G2: =IFERROR(IF(VLOOKUP(A2,Order_Sheet!A:L,8,FALSE)="USD","REVIEW FX","OK"),"CHECK") -> REVIEW FX | H2: =IF(COUNTIF(E2:G2,"*MISMATCH*")+COUNTIF(E2:G2,"CHECK")>0,"ACTION REQUIRED","OK") -> ACTION REQUIRED | I2: =IF(H2="OK","No action","Review Order / PO / Cost Sheet") -> Review Order / PO / Cost Sheet
A3: =Order_Sheet!A3 -> SO-2026-0002 | B3: =IFERROR(VLOOKUP(A3,Order_Sheet!A:L,6,FALSE),"") -> 9914 | C3: =IFERROR(SUMIF(PO_Tracker!C:C,A3,PO_Tracker!I:I),"") -> 15814 | D3: =IFERROR(VLOOKUP(A3,Cost_Sheet!B:J,2,FALSE),"") | E3: =IF(OR(B3="",C3=""),"CHECK",IF(ABS(B3-C3)<=B3*5%,"OK","QTY MISMATCH")) -> QTY MISMATCH | F3: =IFERROR(IF(VLOOKUP(A3,Order_Sheet!A:L,4,FALSE)=INDEX(PO_Tracker!D:D,MATCH(A3,PO_Tracker!C:C,0)),"OK","STYLE MISMATCH"),"CHECK") -> OK | G3: =IFERROR(IF(VLOOKUP(A3,Order_Sheet!A:L,8,FALSE)="USD","REVIEW FX","OK"),"CHECK") -> REVIEW FX | H3: =IF(COUNTIF(E3:G3,"*MISMATCH*")+COUNTIF(E3:G3,"CHECK")>0,"ACTION REQUIRED","OK") -> ACTION REQUIRED | I3: =IF(H3="OK","No action","Review Order / PO / Cost Sheet") -> Review Order / PO / Cost Sheet
A4: =Order_Sheet!A4 -> SO-2026-0003 | B4: =IFERROR(VLOOKUP(A4,Order_Sheet!A:L,6,FALSE),"") -> 1342 | C4: =IFERROR(SUMIF(PO_Tracker!C:C,A4,PO_Tracker!I:I),"") -> 1638 | D4: =IFERROR(VLOOKUP(A4,Cost_Sheet!B:J,2,FALSE),"") | E4: =IF(OR(B4="",C4=""),"CHECK",IF(ABS(B4-C4)<=B4*5%,"OK","QTY MISMATCH")) -> QTY MISMATCH | F4: =IFERROR(IF(VLOOKUP(A4,Order_Sheet!A:L,4,FALSE)=INDEX(PO_Tracker!D:D,MATCH(A4,PO_Tracker!C:C,0)),"OK","STYLE MISMATCH"),"CHECK") -> OK | G4: =IFERROR(IF(VLOOKUP(A4,Order_Sheet!A:L,8,FALSE)="USD","REVIEW FX","OK"),"CHECK") -> REVIEW FX | H4: =IF(COUNTIF(E4:G4,"*MISMATCH*")+COUNTIF(E4:G4,"CHECK")>0,"ACTION REQUIRED","OK") -> ACTION REQUIRED | I4: =IF(H4="OK","No action","Review Order / PO / Cost Sheet") -> Review Order / PO / Cost Sheet
A5: =Order_Sheet!A5 -> SO-2026-0004 | B5: =IFERROR(VLOOKUP(A5,Order_Sheet!A:L,6,FALSE),"") -> 5769 | C5: =IFERROR(SUMIF(PO_Tracker!C:C,A5,PO_Tracker!I:I),"") -> 69247 | D5: =IFERROR(VLOOKUP(A5,Cost_Sheet!B:J,2,FALSE),"") | E5: =IF(OR(B5="",C5=""),"CHECK",IF(ABS(B5-C5)<=B5*5%,"OK","QTY MISMATCH")) -> QTY MISMATCH | F5: =IFERROR(IF(VLOOKUP(A5,Order_Sheet!A:L,4,FALSE)=INDEX(PO_Tracker!D:D,MATCH(A5,PO_Tracker!C:C,0)),"OK","STYLE MISMATCH"),"CHECK") -> OK | G5: =IFERROR(IF(VLOOKUP(A5,Order_Sheet!A:L,8,FALSE)="USD","REVIEW FX","OK"),"CHECK") -> REVIEW FX | H5: =IF(COUNTIF(E5:G5,"*MISMATCH*")+COUNTIF(E5:G5,"CHECK")>0,"ACTION REQUIRED","OK") -> ACTION REQUIRED | I5: =IF(H5="OK","No action","Review Order / PO / Cost Sheet") -> Review Order / PO / Cost Sheet
A6: =Order_Sheet!A6 -> SO-2026-0005 | B6: =IFERROR(VLOOKUP(A6,Order_Sheet!A:L,6,FALSE),"") -> 11218 | C6: =IFERROR(SUMIF(PO_Tracker!C:C,A6,PO_Tracker!I:I),"") -> 75974 | D6: =IFERROR(VLOOKUP(A6,Cost_Sheet!B:J,2,FALSE),"") | E6: =IF(OR(B6="",C6=""),"CHECK",IF(ABS(B6-C6)<=B6*5%,"OK","QTY MISMATCH")) -> QTY MISMATCH | F6: =IFERROR(IF(VLOOKUP(A6,Order_Sheet!A:L,4,FALSE)=INDEX(PO_Tracker!D:D,MATCH(A6,PO_Tracker!C:C,0)),"OK","STYLE MISMATCH"),"CHECK") -> OK | G6: =IFERROR(IF(VLOOKUP(A6,Order_Sheet!A:L,8,FALSE)="USD","REVIEW FX","OK"),"CHECK") -> REVIEW FX | H6: =IF(COUNTIF(E6:G6,"*MISMATCH*")+COUNTIF(E6:G6,"CHECK")>0,"ACTION REQUIRED","OK") -> ACTION REQUIRED | I6: =IF(H6="OK","No action","Review Order / PO / Cost Sheet") -> Review Order / PO / Cost Sheet
A7: =Order_Sheet!A7 -> SO-2026-0006 | B7: =IFERROR(VLOOKUP(A7,Order_Sheet!A:L,6,FALSE),"") -> 4306 | C7: =IFERROR(SUMIF(PO_Tracker!C:C,A7,PO_Tracker!I:I),"") -> 7560 | D7: =IFERROR(VLOOKUP(A7,Cost_Sheet!B:J,2,FALSE),"") | E7: =IF(OR(B7="",C7=""),"CHECK",IF(ABS(B7-C7)<=B7*5%,"OK","QTY MISMATCH")) -> QTY MISMATCH | F7: =IFERROR(IF(VLOOKUP(A7,Order_Sheet!A:L,4,FALSE)=INDEX(PO_Tracker!D:D,MATCH(A7,PO_Tracker!C:C,0)),"OK","STYLE MISMATCH"),"CHECK") -> OK | G7: =IFERROR(IF(VLOOKUP(A7,Order_Sheet!A:L,8,FALSE)="USD","REVIEW FX","OK"),"CHECK") -> REVIEW FX | H7: =IF(COUNTIF(E7:G7,"*MISMATCH*")+COUNTIF(E7:G7,"CHECK")>0,"ACTION REQUIRED","OK") -> ACTION REQUIRED | I7: =IF(H7="OK","No action","Review Order / PO / Cost Sheet") -> Review Order / PO / Cost Sheet
A8: =Order_Sheet!A8 -> SO-2026-0007 | B8: =IFERROR(VLOOKUP(A8,Order_Sheet!A:L,6,FALSE),"") -> 4961 | C8: =IFERROR(SUMIF(PO_Tracker!C:C,A8,PO_Tracker!I:I),"") -> 198755 | D8: =IFERROR(VLOOKUP(A8,Cost_Sheet!B:J,2,FALSE),"") | E8: =IF(OR(B8="",C8=""),"CHECK",IF(ABS(B8-C8)<=B8*5%,"OK","QTY MISMATCH")) -> QTY MISMATCH | F8: =IFERROR(IF(VLOOKUP(A8,Order_Sheet!A:L,4,FALSE)=INDEX(PO_Tracker!D:D,MATCH(A8,PO_Tracker!C:C,0)),"OK","STYLE MISMATCH"),"CHECK") -> OK | G8: =IFERROR(IF(VLOOKUP(A8,Order_Sheet!A:L,8,FALSE)="USD","REVIEW FX","OK"),"CHECK") -> REVIEW FX | H8: =IF(COUNTIF(E8:G8,"*MISMATCH*")+COUNTIF(E8:G8,"CHECK")>0,"ACTION REQUIRED","OK") -> ACTION REQUIRED | I8: =IF(H8="OK","No action","Review Order / PO / Cost Sheet") -> Review Order / PO / Cost Sheet
A9: =Order_Sheet!A9 -> SO-2026-0008 | B9: =IFERROR(VLOOKUP(A9,Order_Sheet!A:L,6,FALSE),"") -> 9075 | C9: =IFERROR(SUMIF(PO_Tracker!C:C,A9,PO_Tracker!I:I),"") -> 0 | D9: =IFERROR(VLOOKUP(A9,Cost_Sheet!B:J,2,FALSE),"") | E9: =IF(OR(B9="",C9=""),"CHECK",IF(ABS(B9-C9)<=B9*5%,"OK","QTY MISMATCH")) -> QTY MISMATCH | F9: =IFERROR(IF(VLOOKUP(A9,Order_Sheet!A:L,4,FALSE)=INDEX(PO_Tracker!D:D,MATCH(A9,PO_Tracker!C:C,0)),"OK","STYLE MISMATCH"),"CHECK") -> CHECK | G9: =IFERROR(IF(VLOOKUP(A9,Order_Sheet!A:L,8,FALSE)="USD","REVIEW FX","OK"),"CHECK") -> REVIEW FX | H9: =IF(COUNTIF(E9:G9,"*MISMATCH*")+COUNTIF(E9:G9,"CHECK")>0,"ACTION REQUIRED","OK") -> ACTION REQUIRED | I9: =IF(H9="OK","No action","Review Order / PO / Cost Sheet") -> Review Order / PO / Cost Sheet
A10: =Order_Sheet!A10 -> SO-2026-0009 | B10: =IFERROR(VLOOKUP(A10,Order_Sheet!A:L,6,FALSE),"") -> 2613 | C10: =IFERROR(SUMIF(PO_Tracker!C:C,A10,PO_Tracker!I:I),"") -> 20099 | D10: =IFERROR(VLOOKUP(A10,Cost_Sheet!B:J,2,FALSE),"") | E10: =IF(OR(B10="",C10=""),"CHECK",IF(ABS(B10-C10)<=B10*5%,"OK","QTY MISMATCH")) -> QTY MISMATCH | F10: =IFERROR(IF(VLOOKUP(A10,Order_Sheet!A:L,4,FALSE)=INDEX(PO_Tracker!D:D,MATCH(A10,PO_Tracker!C:C,0)),"OK","STYLE MISMATCH"),"CHECK") -> OK | G10: =IFERROR(IF(VLOOKUP(A10,Order_Sheet!A:L,8,FALSE)="USD","REVIEW FX","OK"),"CHECK") -> REVIEW FX | H10: =IF(COUNTIF(E10:G10,"*MISMATCH*")+COUNTIF(E10:G10,"CHECK")>0,"ACTION REQUIRED","OK") -> ACTION REQUIRED | I10: =IF(H10="OK","No action","Review Order / PO / Cost Sheet") -> Review Order / PO / Cost Sheet
A11: =Order_Sheet!A11 -> SO-2026-0010 | B11: =IFERROR(VLOOKUP(A11,Order_Sheet!A:L,6,FALSE),"") -> 5933 | C11: =IFERROR(SUMIF(PO_Tracker!C:C,A11,PO_Tracker!I:I),"") -> 80676 | D11: =IFERROR(VLOOKUP(A11,Cost_Sheet!B:J,2,FALSE),"") | E11: =IF(OR(B11="",C11=""),"CHECK",IF(ABS(B11-C11)<=B11*5%,"OK","QTY MISMATCH")) -> QTY MISMATCH | F11: =IFERROR(IF(VLOOKUP(A11,Order_Sheet!A:L,4,FALSE)=INDEX(PO_Tracker!D:D,MATCH(A11,PO_Tracker!C:C,0)),"OK","STYLE MISMATCH"),"CHECK") -> OK | G11: =IFERROR(IF(VLOOKUP(A11,Order_Sheet!A:L,8,FALSE)="USD","REVIEW FX","OK"),"CHECK") -> REVIEW FX | H11: =IF(COUNTIF(E11:G11,"*MISMATCH*")+COUNTIF(E11:G11,"CHECK")>0,"ACTION REQUIRED","OK") -> ACTION REQUIRED | I11: =IF(H11="OK","No action","Review Order / PO / Cost Sheet") -> Review Order / PO / Cost Sheet
A12: =Order_Sheet!A12 -> SO-2026-0011 | B12: =IFERROR(VLOOKUP(A12,Order_Sheet!A:L,6,FALSE),"") -> 3043 | C12: =IFERROR(SUMIF(PO_Tracker!C:C,A12,PO_Tracker!I:I),"") -> 66066 | D12: =IFERROR(VLOOKUP(A12,Cost_Sheet!B:J,2,FALSE),"") | E12: =IF(OR(B12="",C12=""),"CHECK",IF(ABS(B12-C12)<=B12*5%,"OK","QTY MISMATCH")) -> QTY MISMATCH | F12: =IFERROR(IF(VLOOKUP(A12,Order_Sheet!A:L,4,FALSE)=INDEX(PO_Tracker!D:D,MATCH(A12,PO_Tracker!C:C,0)),"OK","STYLE MISMATCH"),"CHECK") -> OK | G12: =IFERROR(IF(VLOOKUP(A12,Order_Sheet!A:L,8,FALSE)="USD","REVIEW FX","OK"),"CHECK") -> REVIEW FX | H12: =IF(COUNTIF(E12:G12,"*MISMATCH*")+COUNTIF(E12:G12,"CHECK")>0,"ACTION REQUIRED","OK") -> ACTION REQUIRED | I12: =IF(H12="OK","No action","Review Order / PO / Cost Sheet") -> Review Order / PO / Cost Sheet
A13: =Order_Sheet!A13 -> SO-2026-0012 | B13: =IFERROR(VLOOKUP(A13,Order_Sheet!A:L,6,FALSE),"") -> 7152 | C13: =IFERROR(SUMIF(PO_Tracker!C:C,A13,PO_Tracker!I:I),"") -> 37697 | D13: =IFERROR(VLOOKUP(A13,Cost_Sheet!B:J,2,FALSE),"") | E13: =IF(OR(B13="",C13=""),"CHECK",IF(ABS(B13-C13)<=B13*5%,"OK","QTY MISMATCH")) -> QTY MISMATCH | F13: =IFERROR(IF(VLOOKUP(A13,Order_Sheet!A:L,4,FALSE)=INDEX(PO_Tracker!D:D,MATCH(A13,PO_Tracker!C:C,0)),"OK","STYLE MISMATCH"),"CHECK") -> OK | G13: =IFERROR(IF(VLOOKUP(A13,Order_Sheet!A:L,8,FALSE)="USD","REVIEW FX","OK"),"CHECK") -> REVIEW FX | H13: =IF(COUNTIF(E13:G13,"*MISMATCH*")+COUNTIF(E13:G13,"CHECK")>0,"ACTION REQUIRED","OK") -> ACTION REQUIRED | I13: =IF(H13="OK","No action","Review Order / PO / Cost Sheet") -> Review Order / PO / Cost Sheet
... A81: =Order_Sheet!A81 -> SO-2026-0080 | B81: =IFERROR(VLOOKUP(A81,Order_Sheet!A:L,6,FALSE),"") -> 1732 | C81: =IFERROR(SUMIF(PO_Tracker!C:C,A81,PO_Tracker!I:I),"") -> 0 | D81: =IFERROR(VLOOKUP(A81,Cost_Sheet!B:J,2,FALSE),"") | E81: =IF(OR(B81="",C81=""),"CHECK",IF(ABS(B81-C81)<=B81*5%,"OK","QTY MISMATCH")) -> QTY MISMATCH | F81: =IFERROR(IF(VLOOKUP(A81,Order_Sheet!A:L,4,FALSE)=INDEX(PO_Tracker!D:D,MATCH(A81,PO_Tracker!C:C,0)),"OK","STYLE MISMATCH"),"CHECK") -> CHECK | G81: =IFERROR(IF(VLOOKUP(A81,Order_Sheet!A:L,8,FALSE)="USD","REVIEW FX","OK"),"CHECK") -> REVIEW FX | H81: =IF(COUNTIF(E81:G81,"*MISMATCH*")+COUNTIF(E81:G81,"CHECK")>0,"ACTION REQUIRED","OK") -> ACTION REQUIRED | I81: =IF(H81="OK","No action","Review Order / PO / Cost Sheet") -> Review Order / PO / Cost Sheet

Sheet Dashboard
A1: GARMENT OPERATIONS & DATA QUALITY DASHBOARD
A3: Orders | C3: Order Qty | E3: PO Qty | G3: PO Coverage
A4: =COUNTA(Order_Sheet!A2:A81) -> 80 | C4: =SUM(Order_Sheet!F2:F81) -> 534843 | E4: =SUM(PO_Tracker!I2:I181) -> 4983258 | G4: =IFERROR(COUNTIF(Accuracy_Check!C2:C81,">0")/COUNTA(Accuracy_Check!A2:A81),0) -> 0.875
A6: Avg Actual Productivity | C6: Avg Target Productivity | E6: Avg Productivity Gap | G6: Total WIP
A7: =AVERAGE(Calculations!G2:G721) -> 0.738875 | C7: =AVERAGE(Calculations!F2:F721) -> 0.80730556 | E7: =AVERAGE(Calculations!H2:H721) -> -0.068430556 | G7: =SUM(Calculations!I2:I721) -> 175221
A9: Total Overtime (min) | C9: Total Idle Time (min) | E9: Total Idle Men | G9: Avg Style Changes
A10: =SUM(Calculations!J2:J721) -> 55504 | C10: =SUM(Calculations!K2:K721) -> 43200 | E10: =SUM(Calculations!L2:L721) -> 2508 | G10: =AVERAGE(Calculations!M2:M721) -> 0.98472222
A12: Action Required Orders | C12: Orders Missing PO | E12: Avg Cost / Piece | G12: Production Rows
